Workbook
Name points: Sheet3!$B$1:$B$5

Sheet Home Page

Sheet Sheet1
A6: Player Name | B6: Games Played | D6: Wins | F6: Points | H6: Rebuys | J6: Add-Ons | L6: Cash Paid | N6: Winnings | P6: Profit/Loss | R6: Bonus Chips | T6: Knock Outs | W6: Points Key | Z6: 2026 League Statistics
A7: Edward Wearing | B7: 1 | F7: =T7+D27+G27+J27+M27+P27+S27+V27+Y27+AB27+AE27+B7 -> 6 | J7: 1 | L7: =(B7*10)+(H7*10)+(J7*10) -> 20 | N7: =C27+F27+I27+L27+O27+R27+U27+X27+AA27+AD27+AG27 -> 0 | P7: =N7-L7 -> -20 | R7: =F7*500 -> 3000 | T7: 1 | V7: =F7 + (D7 * 10000) -> 6 | W7: 1st Place | X7: 10 Points | Y7: =RANK(V7, V$7:V$17, 0) -> 4 | Z7: Money Spent this Season | AC7: =SUM(L7:M17) -> 200
A8: Georgina Wearing | B8: 1 | F8: =B8+T8+D28+G28+J28+M28+P28+S28+V28+Y28+AB28+AE28 -> 7 | J8: 1 | L8: =(B8*10)+(H8*10)+(J8*10) -> 20 | N8: =C28+F28+I28+L28+O28+R28+U28+X28+AA28+AD28+AG28 -> 20 | P8: =N8-L8 -> 0 | R8: =F8*500 -> 3500 | T8: 1 | V8: =F8 + (D8 * 10000) -> 7 | W8: 2nd Place | X8: 6 Points | Y8: =RANK(V8, V$7:V$17, 0) -> 3 | Z8: Most Players in a Single Game | AC8: =MAX(B38,E38,H38,K38,N38,Q38,T38,W38,Z38,AC38,AF38) -> 9 | AD8: Date:
A9: Luke Daly | B9: 1 | F9: =B9+T9+D29+G29+J29+M29+P29+S29+V29+Y29+AB29+AE29 -> 11 | J9: 1 | L9: =(B9*10)+(H9*10)+(J9*10) -> 20 | N9: =C29+F29+I29+L29+O29+R29+U29+X29+AA29+AD29+AG29 -> 50 | P9: =N9-L9 -> 30 | R9: =F9*500 -> 5500 | T9: 3 | V9: =F9 + (D9 * 10000) -> 11 | W9: 3rd Place | X9: 4 Points | Y9: =RANK(V9, V$7:V$17, 0) -> 2 | Z9: Biggest Win | AC9: =MAX(C27:C37,F27:F37,I27:I37,L27:L37,O27:O37,R27:R37,U27:U37,X27:X37,AA27:AA37,AD27:AD37) -> 110 | AD9: Player:
A10: Daniel Horne | B10: 1 | F10: =B10+T10+D30+G30+J30+M30+P30+S30+V30+Y30+AB30+AE30 -> 1 | J10: 1 | L10: =(B10*10)+(H10*10)+(J10*10) -> 20 | N10: =C30+F30+I30+L30+O30+R30+U30+X30+AA30+AD30+AG30 -> 0 | P10: =N10-L10 -> -20 | R10: =F10*500 -> 500 | V10: =F10 + (D10 * 10000) -> 1 | W10: 4th Place | X10: 3 Points | Y10: =RANK(V10, V$7:V$17, 0) -> 6 | Z10: Total Points Earned This Season | AC10: =SUM(F7:G17) -> 49
A11: Darren Daly | B11: 1 | F11: =B11+T11+D31+G31+J31+M31+P31+S31+V31+Y31+AB31+AE31 -> 4 | J11: 1 | L11: =(B11*10)+(H11*10)+(J11*10) -> 20 | N11: =C31+F31+I31+L31+O31+R31+U31+X31+AA31+AD31+AG31 -> 0 | P11: =N11-L11 -> -20 | R11: =F11*500 -> 2000 | V11: =F11 + (D11 * 10000) -> 4 | W11: 5th Place | X11: 2 Points | Y11: =RANK(V11, V$7:V$17, 0) -> 5 | Z11: Total Re-Buys This Season | AC11: =SUM(H7:I17) -> 2
A12: Chris Daly | B12: 1 | F12: =B12+T12+D32+G32+J32+M32+P32+S32+V32+Y32+AB32+AE32 -> 1 | H12: 1 | J12: 1 | L12: =(B12*10)+(H12*10)+(J12*10) -> 30 | N12: =C32+F32+I32+L32+O32+R32+U32+X32+AA32+AD32+AG32 -> 0 | P12: =N12-L12 -> -30 | R12: =F12*500 -> 500 | V12: =F12 + (D12 * 10000) -> 1 | W12: 6th Place or less will receive no points | Y12: =RANK(V12, V$7:V$17, 0) -> 6 | Z12: Total Add-Ons This Season | AC12: =SUM(J7:K17) -> 9
A13: Stephen Flood | F13: =B13+T13+D33+G33+J33+M33+P33+S33+V33+Y33+AB33+AE33 -> 0 | L13: =(B13*10)+(H13*10)+(J13*10) -> 0 | N13: =C33+F33+I33+L33+O33+R33+U33+X33+AA33+AD33+AG33 -> 0 | P13: =N13-L13 -> 0 | R13: =F13*500 -> 0 | V13: =F13 + (D13 * 10000) -> 0 | Y13: =RANK(V13, V$7:V$17, 0) -> 10
A14: Phil Landsberger | F14: =B14+T14+D34+G34+J34+M34+P34+S34+V34+Y34+AB34+AE34 -> 0 | L14: =(B14*10)+(H14*10)+(J14*10) -> 0 | N14: =C34+F34+I34+L34+O34+R34+U34+X34+AA34+AD34+AG34 -> 0 | P14: =N14-L14 -> 0 | R14: =F14*500 -> 0 | V14: =F14 + (D14 * 10000) -> 0 | Y14: =RANK(V14, V$7:V$17, 0) -> 10
A15: Liam Duxbury | B15: 1 | D15: 1 | F15: =B15+T15+D35+G35+J35+M35+P35+S35+V35+Y35+AB35+AE35 -> 17 | H15: 1 | J15: 1 | L15: =(B15*10)+(H15*10)+(J15*10) -> 30 | N15: =C35+F35+I35+L35+O35+R35+U35+X35+AA35+AD35+AG35 -> 110 | P15: =N15-L15 -> 80 | R15: =F15*500 -> 8500 | T15: 5 | V15: =F15 + (D15 * 10000) -> 10017 | W15: Players will receive 1 point for each participant they knock out in each game. | Y15: =RANK(V15, V$7:V$17, 0) -> 1
A16: Nathen Benson | B16: 1 | F16: =B16+T16+D36+G36+J36+M36+P36+S36+V36+Y36+AB36+AE36 -> 1 | J16: 1 | L16: =(B16*10)+(H16*10)+(J16*10) -> 20 | N16: =C36+F36+I36+L36+O36+R36+U36+X36+AA36+AD36+AG36 -> 0 | P16: =N16-L16 -> -20 | R16: =F16*500 -> 500 | V16: =F16 + (D16 * 10000) -> 1 | Y16: =RANK(V16, V$7:V$17, 0) -> 6
A17: Dave Taylor | B17: 1 | F17: =B17+T17+D37+G37+J37+M37+P37+S37+V37+Y37+AB37+AE37 -> 1 | J17: 1 | L17: =(B17*10)+(H17*10)+(J17*10) -> 20 | N17: =C37+F37+I37+L37+O37+R37+U37+X37+AA37+AD37+AG37 -> 0 | P17: =N17-L17 -> -20 | R17: =F17*500 -> 500 | V17: =F17 + (D17 * 10000) -> 1 | Y17: =RANK(V17, V$7:V$17, 0) -> 6
AF21: Season Final
A22: Date | B22: 46046 | E22: 46074 | H22: 46102 | K22: 46137 | N22: 46165 | Q22: 46200 | T22: 46228 | W22: 46256 | Z22: 46291 | AC22: 46319
A23: Prize Pot | B23: 180
A24: Side Pot | B24: 20
A25: Total Side Pot | B25: =B24 -> 20 | E25: =B25+E24 -> 20 | H25: =E25+H24 -> 20 | K25: =H25+K24 -> 20 | N25: =K25+N24 -> 20 | Q25: =N25+Q24 -> 20 | T25: =Q25+T24 -> 20 | W25: =T25+W24 -> 20 | Z25: =W25+Z24 -> 20 | AC25: =Z25+AC24 -> 20 | AF25: =AC25+AF23 -> 20
B26: Place | C26: Winnings | D26: Points | E26: Place | F26: Winnings | G26: Points | H26: Place | I26: Winnings | J26: Points | K26: Place | L26: Winnings | M26: Points | N26: Place | O26: Winnings | P26: Points | Q26: Place | R26: Winnings | S26: Points | T26: Place | U26: Winnings | V26: Points | W26: Place | X26: Winnings | Y26: Points | Z26: Place | AA26: Winnings | AB26: Points | AC26: Place | AD26: Winnings | AE26: Points | AF26: Place | AG26: Winnings
A27: Edward Wearing | B27: 4 | D27: =IF(B27="", 0, IFERROR(VLOOKUP(B27, Sheet3!A1:B5, 2, FALSE) + 1, 0)) -> 4 | G27: =IF(E27="", 0, IFERROR(VLOOKUP(E27, Sheet3!A1:B5, 2, FALSE) + 1, 0)) -> 0 | J27: =IF(H27="", 0, IFERROR(VLOOKUP(H27, Sheet3!A1:B5, 2, FALSE) + 1, 0)) -> 0 | M27: =IF(K27="", 0, IFERROR(VLOOKUP(K27, Sheet3!A1:B5, 2, FALSE) + 1, 0)) -> 0 | P27: =IF(N27="", 0, IFERROR(VLOOKUP(N27, Sheet3!A1:B5, 2, FALSE) + 1, 0)) -> 0 | S27: =IF(Q27="", 0, IFERROR(VLOOKUP(Q27, Sheet3!A1:B5, 2, FALSE) + 1, 0)) -> 0 | V27: =IF(T27="", 0, IFERROR(VLOOKUP(T27, Sheet3!A1:B5, 2, FALSE) + 1, 0)) -> 0 | Y27: =IF(W27="", 0, IFERROR(VLOOKUP(W27, Sheet3!A1:B5, 2, FALSE) + 1, 0)) -> 0 | AB27: =IF(Z27="", 0, IFERROR(VLOOKUP(Z27, Sheet3!A1:B5, 2, FALSE) + 1, 0)) -> 0 | AE27: =IF(AC27="", 0, IFERROR(VLOOKUP(AC27, Sheet3!A1:B5, 2, FALSE) + 1, 0)) -> 0
A28: Georgina Wearing | B28: 3 | C28: 20 | D28: =IF(B28="", 0, IFERROR(VLOOKUP(B28, Sheet3!A1:B5, 2, FALSE) + 1, 0)) -> 5 | G28: =IF(E28="", 0, IFERROR(VLOOKUP(E28, Sheet3!A1:B5, 2, FALSE) + 1, 0)) -> 0 | J28: =IF(H28="", 0, IFERROR(VLOOKUP(H28, Sheet3!A1:B5, 2, FALSE) + 1, 0)) -> 0 | M28: =IF(K28="", 0, IFERROR(VLOOKUP(K28, Sheet3!A1:B5, 2, FALSE) + 1, 0)) -> 0 | P28: =IF(N28="", 0, IFERROR(VLOOKUP(N28, Sheet3!A1:B5, 2, FALSE) + 1, 0)) -> 0 | S28: =IF(Q28="", 0, IFERROR(VLOOKUP(Q28, Sheet3!A1:B5, 2, FALSE) + 1, 0)) -> 0 | V28: =IF(T28="", 0, IFERROR(VLOOKUP(T28, Sheet3!A1:B5, 2, FALSE) + 1, 0)) -> 0 | Y28: =IF(W28="", 0, IFERROR(VLOOKUP(W28, Sheet3!A1:B5, 2, FALSE) + 1, 0)) -> 0 | AB28: =IF(Z28="", 0, IFERROR(VLOOKUP(Z28, Sheet3!A1:B5, 2, FALSE) + 1, 0)) -> 0 | AE28: =IF(AC28="", 0, IFERROR(VLOOKUP(AC28, Sheet3!A1:B5, 2, FALSE) + 1, 0)) -> 0
A29: Luke Daly | B29: 2 | C29: 50 | D29: =IF(B29="", 0, IFERROR(VLOOKUP(B29, Sheet3!A1:B5, 2, FALSE) + 1, 0)) -> 7 | G29: =IF(E29="", 0, IFERROR(VLOOKUP(E29, Sheet3!A1:B5, 2, FALSE) + 1, 0)) -> 0 | J29: =IF(H29="", 0, IFERROR(VLOOKUP(H29, Sheet3!A1:B5, 2, FALSE) + 1, 0)) -> 0 | M29: =IF(K29="", 0, IFERROR(VLOOKUP(K29, Sheet3!A1:B5, 2, FALSE) + 1, 0)) -> 0 | P29: =IF(N29="", 0, IFERROR(VLOOKUP(N29, Sheet3!A1:B5, 2, FALSE) + 1, 0)) -> 0 | S29: =IF(Q29="", 0, IFERROR(VLOOKUP(Q29, Sheet3!A1:B5, 2, FALSE) + 1, 0)) -> 0 | V29: =IF(T29="", 0, IFERROR(VLOOKUP(T29, Sheet3!A1:B5, 2, FALSE) + 1, 0)) -> 0 | Y29: =IF(W29="", 0, IFERROR(VLOOKUP(W29, Sheet3!A1:B5, 2, FALSE) + 1, 0)) -> 0 | AB29: =IF(Z29="", 0, IFERROR(VLOOKUP(Z29, Sheet3!A1:B5, 2, FALSE) + 1, 0)) -> 0 | AE29: =IF(AC29="", 0, IFERROR(VLOOKUP(AC29, Sheet3!A1:B5, 2, FALSE) + 1, 0)) -> 0
A30: Daniel Horne | B30: 9 | D30: =IF(B30="", 0, IFERROR(VLOOKUP(B30, Sheet3!A1:B5, 2, FALSE) + 1, 0)) -> 0 | G30: =IF(E30="", 0, IFERROR(VLOOKUP(E30, Sheet3!A1:B5, 2, FALSE) + 1, 0)) -> 0 | J30: =IF(H30="", 0, IFERROR(VLOOKUP(H30, Sheet3!A1:B5, 2, FALSE) + 1, 0)) -> 0 | M30: =IF(K30="", 0, IFERROR(VLOOKUP(K30, Sheet3!A1:B5, 2, FALSE) + 1, 0)) -> 0 | P30: =IF(N30="", 0, IFERROR(VLOOKUP(N30, Sheet3!A1:B5, 2, FALSE) + 1, 0)) -> 0 | S30: =IF(Q30="", 0, IFERROR(VLOOKUP(Q30, Sheet3!A1:B5, 2, FALSE) + 1, 0)) -> 0 | V30: =IF(T30="", 0, IFERROR(VLOOKUP(T30, Sheet3!A1:B5, 2, FALSE) + 1, 0)) -> 0 | Y30: =IF(W30="", 0, IFERROR(VLOOKUP(W30, Sheet3!A1:B5, 2, FALSE) + 1, 0)) -> 0 | AB30: =IF(Z30="", 0, IFERROR(VLOOKUP(Z30, Sheet3!A1:B5, 2, FALSE) + 1, 0)) -> 0 | AE30: =IF(AC30="", 0, IFERROR(VLOOKUP(AC30, Sheet3!A1:B5, 2, FALSE) + 1, 0)) -> 0
A31: Darren Daly | B31: 5 | D31: =IF(B31="", 0, IFERROR(VLOOKUP(B31, Sheet3!A1:B5, 2, FALSE) + 1, 0)) -> 3 | G31: =IF(E31="", 0, IFERROR(VLOOKUP(E31, Sheet3!A1:B5, 2, FALSE) + 1, 0)) -> 0 | J31: =IF(H31="", 0, IFERROR(VLOOKUP(H31, Sheet3!A1:B5, 2, FALSE) + 1, 0)) -> 0 | M31: =IF(K31="", 0, IFERROR(VLOOKUP(K31, Sheet3!A1:B5, 2, FALSE) + 1, 0)) -> 0 | P31: =IF(N31="", 0, IFERROR(VLOOKUP(N31, Sheet3!A1:B5, 2, FALSE) + 1, 0)) -> 0 | S31: =IF(Q31="", 0, IFERROR(VLOOKUP(Q31, Sheet3!A1:B5, 2, FALSE) + 1, 0)) -> 0 | V31: =IF(T31="", 0, IFERROR(VLOOKUP(T31, Sheet3!A1:B5, 2, FALSE) + 1, 0)) -> 0 | Y31: =IF(W31="", 0, IFERROR(VLOOKUP(W31, Sheet3!A1:B5, 2, FALSE) + 1, 0)) -> 0 | AB31: =IF(Z31="", 0, IFERROR(VLOOKUP(Z31, Sheet3!A1:B5, 2, FALSE) + 1, 0)) -> 0 | AE31: =IF(AC31="", 0, IFERROR(VLOOKUP(AC31, Sheet3!A1:B5, 2, FALSE) + 1, 0)) -> 0
A32: Chris Daly | B32: 6 | D32: =IF(B32="", 0, IFERROR(VLOOKUP(B32, Sheet3!A1:B5, 2, FALSE) + 1, 0)) -> 0 | G32: =IF(E32="", 0, IFERROR(VLOOKUP(E32, Sheet3!A1:B5, 2, FALSE) + 1, 0)) -> 0 | J32: =IF(H32="", 0, IFERROR(VLOOKUP(H32, Sheet3!A1:B5, 2, FALSE) + 1, 0)) -> 0 | M32: =IF(K32="", 0, IFERROR(VLOOKUP(K32, Sheet3!A1:B5, 2, FALSE) + 1, 0)) -> 0 | P32: =IF(N32="", 0, IFERROR(VLOOKUP(N32, Sheet3!A1:B5, 2, FALSE) + 1, 0)) -> 0 | S32: =IF(Q32="", 0, IFERROR(VLOOKUP(Q32, Sheet3!A1:B5, 2, FALSE) + 1, 0)) -> 0 | V32: =IF(T32="", 0, IFERROR(VLOOKUP(T32, Sheet3!A1:B5, 2, FALSE) + 1, 0)) -> 0 | Y32: =IF(W32="", 0, IFERROR(VLOOKUP(W32, Sheet3!A1:B5, 2, FALSE) + 1, 0)) -> 0 | AB32: =IF(Z32="", 0, IFERROR(VLOOKUP(Z32, Sheet3!A1:B5, 2, FALSE) + 1, 0)) -> 0 | AE32: =IF(AC32="", 0, IFERROR(VLOOKUP(AC32, Sheet3!A1:B5, 2, FALSE) + 1, 0)) -> 0
A33: Stephen Flood | D33: =IF(B33="", 0, IFERROR(VLOOKUP(B33, Sheet3!A1:B5, 2, FALSE) + 1, 0)) -> 0 | G33: =IF(E33="", 0, IFERROR(VLOOKUP(E33, Sheet3!A1:B5, 2, FALSE) + 1, 0)) -> 0 | J33: =IF(H33="", 0, IFERROR(VLOOKUP(H33, Sheet3!A1:B5, 2, FALSE) + 1, 0)) -> 0 | M33: =IF(K33="", 0, IFERROR(VLOOKUP(K33, Sheet3!A1:B5, 2, FALSE) + 1, 0)) -> 0 | P33: =IF(N33="", 0, IFERROR(VLOOKUP(N33, Sheet3!A1:B5, 2, FALSE) + 1, 0)) -> 0 | S33: =IF(Q33="", 0, IFERROR(VLOOKUP(Q33, Sheet3!A1:B5, 2, FALSE) + 1, 0)) -> 0 | V33: =IF(T33="", 0, IFERROR(VLOOKUP(T33, Sheet3!A1:B5, 2, FALSE) + 1, 0)) -> 0 | Y33: =IF(W33="", 0, IFERROR(VLOOKUP(W33, Sheet3!A1:B5, 2, FALSE) + 1, 0)) -> 0 | AB33: =IF(Z33="", 0, IFERROR(VLOOKUP(Z33, Sheet3!A1:B5, 2, FALSE) + 1, 0)) -> 0 | AE33: =IF(AC33="", 0, IFERROR(VLOOKUP(AC33, Sheet3!A1:B5, 2, FALSE) + 1, 0)) -> 0
A34: Phil Landsberger | D34: =IF(B34="", 0, IFERROR(VLOOKUP(B34, Sheet3!A1:B5, 2, FALSE) + 1, 0)) -> 0 | G34: =IF(E34="", 0, IFERROR(VLOOKUP(E34, Sheet3!A1:B5, 2, FALSE) + 1, 0)) -> 0 | J34: =IF(H34="", 0, IFERROR(VLOOKUP(H34, Sheet3!A1:B5, 2, FALSE) + 1, 0)) -> 0 | M34: =IF(K34="", 0, IFERROR(VLOOKUP(K34, Sheet3!A1:B5, 2, FALSE) + 1, 0)) -> 0 | P34: =IF(N34="", 0, IFERROR(VLOOKUP(N34, Sheet3!A1:B5, 2, FALSE) + 1, 0)) -> 0 | S34: =IF(Q34="", 0, IFERROR(VLOOKUP(Q34, Sheet3!A1:B5, 2, FALSE) + 1, 0)) -> 0 | V34: =IF(T34="", 0, IFERROR(VLOOKUP(T34, Sheet3!A1:B5, 2, FALSE) + 1, 0)) -> 0 | Y34: =IF(W34="", 0, IFERROR(VLOOKUP(W34, Sheet3!A1:B5, 2, FALSE) + 1, 0)) -> 0 | AB34: =IF(Z34="", 0, IFERROR(VLOOKUP(Z34, Sheet3!A1:B5, 2, FALSE) + 1, 0)) -> 0 | AE34: =IF(AC34="", 0, IFERROR(VLOOKUP(AC34, Sheet3!A1:B5, 2, FALSE) + 1, 0)) -> 0
A35: Liam Duxbury | B35: 1 | C35: 110 | D35: =IF(B35="", 0, IFERROR(VLOOKUP(B35, Sheet3!A1:B5, 2, FALSE) + 1, 0)) -> 11 | G35: =IF(E35="", 0, IFERROR(VLOOKUP(E35, Sheet3!A1:B5, 2, FALSE) + 1, 0)) -> 0 | J35: =IF(H35="", 0, IFERROR(VLOOKUP(H35, Sheet3!A1:B5, 2, FALSE) + 1, 0)) -> 0 | M35: =IF(K35="", 0, IFERROR(VLOOKUP(K35, Sheet3!A1:B5, 2, FALSE) + 1, 0)) -> 0 | P35: =IF(N35="", 0, IFERROR(VLOOKUP(N35, Sheet3!A1:B5, 2, FALSE) + 1, 0)) -> 0 | S35: =IF(Q35="", 0, IFERROR(VLOOKUP(Q35, Sheet3!A1:B5, 2, FALSE) + 1, 0)) -> 0 | V35: =IF(T35="", 0, IFERROR(VLOOKUP(T35, Sheet3!A1:B5, 2, FALSE) + 1, 0)) -> 0 | Y35: =IF(W35="", 0, IFERROR(VLOOKUP(W35, Sheet3!A1:B5, 2, FALSE) + 1, 0)) -> 0 | AB35: =IF(Z35="", 0, IFERROR(VLOOKUP(Z35, Sheet3!A1:B5, 2, FALSE) + 1, 0)) -> 0 | AE35: =IF(AC35="", 0, IFERROR(VLOOKUP(AC35, Sheet3!A1:B5, 2, FALSE) + 1, 0)) -> 0
A36: Nathen Benson | B36: 8 | D36: =IF(B36="", 0, IFERROR(VLOOKUP(B36, Sheet3!A1:B5, 2, FALSE) + 1, 0)) -> 0 | G36: =IF(E36="", 0, IFERROR(VLOOKUP(E36, Sheet3!A1:B5, 2, FALSE) + 1, 0)) -> 0 | J36: =IF(H36="", 0, IFERROR(VLOOKUP(H36, Sheet3!A1:B5, 2, FALSE) + 1, 0)) -> 0 | M36: =IF(K36="", 0, IFERROR(VLOOKUP(K36, Sheet3!A1:B5, 2, FALSE) + 1, 0)) -> 0 | P36: =IF(N36="", 0, IFERROR(VLOOKUP(N36, Sheet3!A1:B5, 2, FALSE) + 1, 0)) -> 0 | S36: =IF(Q36="", 0, IFERROR(VLOOKUP(Q36, Sheet3!A1:B5, 2, FALSE) + 1, 0)) -> 0 | V36: =IF(T36="", 0, IFERROR(VLOOKUP(T36, Sheet3!A1:B5, 2, FALSE) + 1, 0)) -> 0 | Y36: =IF(W36="", 0, IFERROR(VLOOKUP(W36, Sheet3!A1:B5, 2, FALSE) + 1, 0)) -> 0 | AB36: =IF(Z36="", 0, IFERROR(VLOOKUP(Z36, Sheet3!A1:B5, 2, FALSE) + 1, 0)) -> 0 | AE36: =IF(AC36="", 0, IFERROR(VLOOKUP(AC36, Sheet3!A1:B5, 2, FALSE) + 1, 0)) -> 0
A37: Dave Taylor | B37: 7 | D37: =IF(B37="", 0, IFERROR(VLOOKUP(B37, Sheet3!A1:B5, 2, FALSE) + 1, 0)) -> 0 | G37: =IF(E37="", 0, IFERROR(VLOOKUP(E37, Sheet3!A1:B5, 2, FALSE) + 1, 0)) -> 0 | J37: =IF(H37="", 0, IFERROR(VLOOKUP(H37, Sheet3!A1:B5, 2, FALSE) + 1, 0)) -> 0 | M37: =IF(K37="", 0, IFERROR(VLOOKUP(K37, Sheet3!A1:B5, 2, FALSE) + 1, 0)) -> 0 | P37: =IF(N37="", 0, IFERROR(VLOOKUP(N37, Sheet3!A1:B5, 2, FALSE) + 1, 0)) -> 0 | S37: =IF(Q37="", 0, IFERROR(VLOOKUP(Q37, Sheet3!A1:B5, 2, FALSE) + 1, 0)) -> 0 | V37: =IF(T37="", 0, IFERROR(VLOOKUP(T37, Sheet3!A1:B5, 2, FALSE) + 1, 0)) -> 0 | Y37: =IF(W37="", 0, IFERROR(VLOOKUP(W37, Sheet3!A1:B5, 2, FALSE) + 1, 0)) -> 0 | AB37: =IF(Z37="", 0, IFERROR(VLOOKUP(Z37, Sheet3!A1:B5, 2, FALSE) + 1, 0)) -> 0 | AE37: =IF(AC37="", 0, IFERROR(VLOOKUP(AC37, Sheet3!A1:B5, 2, FALSE) + 1, 0)) -> 0
A38: No Of Players | B38: =COUNT(B27:B37) -> 9 | E38: =COUNT(E27:E37) -> 0 | H38: =COUNT(H27:H37) -> 0 | K38: =COUNT(K27:K37) -> 0 | N38: =COUNT(N27:N37) -> 0 | Q38: =COUNT(Q27:Q37) -> 0 | T38: =COUNT(T27:T37) -> 0 | W38: =COUNT(W27:W37) -> 0 | Z38: =COUNT(Z27:Z37) -> 0 | AC38: =COUNT(AC27:AC37) -> 0 | AF38: =COUNT(AF27:AF37) -> 0

Sheet Sheet3
A1: 1 | B1: 10
A2: 2 | B2: 6
A3: 3 | B3: 4
A4: 4 | B4: 3
A5: 5 | B5: 2

Sheet Edward Wearing 
A1: EDWARD WEARING
A2: E.P.T.2026 Leaderboard Profile
A3: Current Rank | B3: Current League Points
A4: =Sheet1!Y7 -> 4 | B4: =Sheet1!F7 -> 6
A6: Season Profit/Loss | B6: Win Percentage
A7: =Sheet1!P7 -> -20 | B7: =IFERROR(Sheet1!D7/Sheet1!B7, 0) -> 0
A9: Average Finishing Position | B9: Average Winnings
A10: =IFERROR(AVERAGE(Sheet1!B27,Sheet1!E27,Sheet1!H27,Sheet1!K27,Sheet1!N27,Sheet1!Q27,Sheet1!T27,Sheet1!W27,Sheet1!Z27,Sheet1!AC27,Sheet1!AF27), 0) -> 4 | B10: =IFERROR(AVERAGE(Sheet1!C27,Sheet1!F27,Sheet1!I27,Sheet1!L27,Sheet1!O27,Sheet1!R27,Sheet1!U27,Sheet1!X27,Sheet1!AA27,Sheet1!AD27,Sheet1!AG27), 0) -> 0
A12: Average Points | B12: Average Knockouts per game
A13: =AVERAGE(Sheet1!D27,Sheet1!G27,Sheet1!J27,Sheet1!M27,Sheet1!P27,Sheet1!S27,Sheet1!V27,Sheet1!Y27,Sheet1!AB27,Sheet1!AE27) -> 0.4 | B13: =AVERAGE(B27:L36) -> 1
A15: Most Re-Buys in a single game | B15: Bubble Finishes
A16: =MAX(B23:L23) -> 0 | B16: 1
A18: Rival Player | B18: Bullied Player
A19: =INDEX(A27:A36, MATCH(MAX(M27:M36), M27:M36, 0)) -> Dave Taylor | B19: =INDEX(A39:A48, MATCH(MAX(M39:M48), M39:M48, 0)) -> Liam Duxbury
A21: Date | B21: 46046 | C21: 46074 | D21: 46102 | E21: 46137 | F21: 46165 | G21: 46200 | H21: 46228 | I21: 46256 | J21: 46291 | K21: 46319 | L21: Final
A22: Total Money Spent | B22: 20
A23: Rebuys | B23: 0
A24: Add-Ons | B24: 10
A25: Profit/Loss | B25: =Sheet1!C27-'Edward Wearing '!B22 -> -20 | C25: =Sheet1!F27-'Edward Wearing '!C22 -> 0 | D25: =Sheet1!I27-'Edward Wearing '!D22 -> 0 | E25: =Sheet1!L27-'Edward Wearing '!E22 -> 0 | F25: =Sheet1!O27-'Edward Wearing '!F22 -> 0 | G25: =Sheet1!R27-'Edward Wearing '!G22 -> 0 | H25: =Sheet1!U27-'Edward Wearing '!H22 -> 0 | I25: =Sheet1!X27-'Edward Wearing '!I22 -> 0 | J25: =Sheet1!AA27-'Edward Wearing '!J22 -> 0 | K25: =Sheet1!AD27-'Edward Wearing '!K22 -> 0 | L25: =Sheet1!AG27-'Edward Wearing '!L22 -> 0
A26: Player Knockouts | M26: Total
A27: Georgina Wearing | M27: =SUM(B27:L27) -> 0 | N27: =M27-M39 -> 0
A28: Luke Daly | M28: =SUM(B28:L28) -> 0 | N28: =M28-M40 -> 0
A29: Daniel Horne | M29: =SUM(B29:L29) -> 0 | N29: =M29-M41 -> 0
A30: Darren Daly | M30: =SUM(B30:L30) -> 0 | N30: =M30-M42 -> 0
A31: Chris Daly | M31: =SUM(B31:L31) -> 0 | N31: =M31-M43 -> 0
A32: Stephen Flood | M32: =SUM(B32:L32) -> 0 | N32: =M32-M44 -> 0
A33: Phill Landsberger | M33: =SUM(B33:L33) -> 0 | N33: =M33-M45 -> 0
A34: Liam Duxbury | M34: =SUM(B34:L34) -> 0 | N34: =M34-M46 -> -1
A35: Nathen Benson | M35: =SUM(B35:L35) -> 0 | N35: =M35-M47 -> 0
A36: Dave Taylor | B36: 1 | M36: =SUM(B36:L36) -> 1 | N36: =M36-M48 -> 1
A37: Total | B37: =SUM(B27:B36) -> 1 | C37: =SUM(C27:C36) -> 0 | D37: =SUM(D27:D36) -> 0 | E37: =SUM(E27:E36) -> 0 | F37: =SUM(F27:F36) -> 0 | G37: =SUM(G27:G36) -> 0 | H37: =SUM(H27:H36) -> 0 | I37: =SUM(I27:I36) -> 0 | ... L37: =SUM(L27:L36) -> 0
A38: Knocked Out By | M38: Total
A39: Georgina Wearing | M39: =SUM(B39:L39) -> 0
A40: Luke Daly | M40: =SUM(B40:L40) -> 0
A41: Daniel Horne | M41: =SUM(B41:L41) -> 0
A42: Darren Daly | M42: =SUM(B42:L42) -> 0
A43: Chris Daly | M43: =SUM(B43:L43) -> 0
A44: Stephen Flood | M44: =SUM(B44:L44) -> 0
A45: Phill Landsberger | M45: =SUM(B45:L45) -> 0
A46: Liam Duxbury | B46: 1 | M46: =SUM(B46:L46) -> 1
...

Sheet Georgina Wearing
A1: GEORGINA WEARING
A2: E.P.T.2026 Leaderboard Profile
A3: Current Rank | B3: Current League Points
A4: =Sheet1!Y8 -> 3 | B4: =Sheet1!F8 -> 7
A6: Season Profit/Loss | B6: Win Percentage
A7: =Sheet1!P8 -> 0 | B7: =IFERROR(Sheet1!D8/Sheet1!B8, 0) -> 0
A9: Average Finishing Position | B9: Average Winnings
A10: =IFERROR(AVERAGE(Sheet1!B28,Sheet1!E28,Sheet1!H28,Sheet1!K28,Sheet1!N28,Sheet1!Q28,Sheet1!T28,Sheet1!W28,Sheet1!Z28,Sheet1!AC28,Sheet1!AF28), 0) -> 3 | B10: =IFERROR(AVERAGE(Sheet1!C28,Sheet1!F28,Sheet1!I28,Sheet1!L28,Sheet1!O28,Sheet1!R28,Sheet1!U28,Sheet1!X28,Sheet1!AA28,Sheet1!AD28,Sheet1!AG28), 0) -> 20
A12: Average Points | B12: Average Knockouts per game
A13: =AVERAGE(Sheet1!D28,Sheet1!G28,Sheet1!J28,Sheet1!M28,Sheet1!P28,Sheet1!S28,Sheet1!V28,Sheet1!Y28,Sheet1!AB28,Sheet1!AE28) -> 0.5 | B13: =AVERAGE(B27:L36) -> 1
A15: Most Re-Buys in a single game | B15: Bubble Finishes
A16: =MAX(B23:L23) -> 0 | B16: 0
A18: Rival Player | B18: Bullied Player
A19: =INDEX(A27:A36, MATCH(MAX(M27:M36), M27:M36, 0)) -> Chris Daly | B19: =INDEX(A39:A48, MATCH(MAX(M39:M48), M39:M48, 0)) -> Luke Daly
A21: Date | B21: 46047 | C21: 46074 | D21: 46102 | E21: 46137 | F21: 46165 | G21: 46200 | H21: 46228 | I21: 46256 | J21: 46291 | K21: 46320 | L21: Final
A22: Total Money Spent | B22: 20
A23: Rebuys | B23: 0
A24: Add-Ons | B24: 10
A25: Profit/Loss | B25: =Sheet1!C28-B22 -> 0 | C25: =Sheet1!F28-C22 -> 0 | D25: =Sheet1!I28-D22 -> 0 | E25: =Sheet1!L28-E22 -> 0 | F25: =Sheet1!O28-F22 -> 0 | G25: =Sheet1!R28-G22 -> 0 | H25: =Sheet1!U28-H22 -> 0 | I25: =Sheet1!X28-I22 -> 0 | J25: =Sheet1!AA28-J22 -> 0 | K25: =Sheet1!AD28-K22 -> 0 | L25: =Sheet1!AG28-L22 -> 0
A26: Player Knockouts | M26: Total
A27: Edward Wearing | M27: =SUM(B27:L27) -> 0 | N27: =M27-M39 -> 0
A28: Luke Daly | M28: =SUM(B28:L28) -> 0 | N28: =M28-M40 -> -1
A29: Daniel Horne | M29: =SUM(B29:L29) -> 0 | N29: =M29-M41 -> 0
A30: Darren Daly | M30: =SUM(B30:L30) -> 0 | N30: =M30-M42 -> 0
A31: Chris Daly | B31: 1 | M31: =SUM(B31:L31) -> 1 | N31: =M31-M43 -> 1
A32: Stephen Flood | M32: =SUM(B32:L32) -> 0 | N32: =M32-M44 -> 0
A33: Phill Landsberger | M33: =SUM(B33:L33) -> 0 | N33: =M33-M45 -> 0
A34: Liam Duxbury | M34: =SUM(B34:L34) -> 0 | N34: =M34-M46 -> 0
A35: Nathen Benson | M35: =SUM(B35:L35) -> 0 | N35: =M35-M47 -> 0
A36: Dave Taylor | M36: =SUM(B36:L36) -> 0 | N36: =M36-M48 -> 0
A37: Total | B37: =SUM(B27:B36) -> 1 | C37: =SUM(C27:C36) -> 0 | D37: =SUM(D27:D36) -> 0 | E37: =SUM(E27:E36) -> 0 | F37: =SUM(F27:F36) -> 0 | G37: =SUM(G27:G36) -> 0 | H37: =SUM(H27:H36) -> 0 | I37: =SUM(I27:I36) -> 0 | ... L37: =SUM(L27:L36) -> 0
A38: Knocked Out By | M38: Total
A39: Edward Wearing | M39: =SUM(B39:L39) -> 0
A40: Luke Daly | B40: 1 | M40: =SUM(B40:L40) -> 1
A41: Daniel Horne | M41: =SUM(B41:L41) -> 0
A42: Darren Daly | M42: =SUM(B42:L42) -> 0
A43: Chris Daly | M43: =SUM(B43:L43) -> 0
A44: Stephen Flood | M44: =SUM(B44:L44) -> 0
A45: Phill Landsberger | M45: =SUM(B45:L45) -> 0
A46: Liam Duxbury | M46: =SUM(B46:L46) -> 0
...

Sheet Luke Daly
A1: LUKE DALY
A2: E.P.T.2026 Leaderboard Profile
A3: Current Rank | B3: Current League Points
A4: =Sheet1!Y9 -> 2 | B4: =Sheet1!F9 -> 11
A6: Season Profit/Loss | B6: Win Percentage
A7: =Sheet1!P9 -> 30 | B7: =IFERROR(Sheet1!D9/Sheet1!B9, 0) -> 0
A9: Average Finishing Position | B9: Average Winnings
A10: =IFERROR(AVERAGE(Sheet1!B29,Sheet1!E29,Sheet1!H29,Sheet1!K29,Sheet1!N29,Sheet1!Q29,Sheet1!T29,Sheet1!W29,Sheet1!Z29,Sheet1!AC29,Sheet1!AF29), 0) -> 2 | B10: =IFERROR(AVERAGE(Sheet1!C29,Sheet1!F29,Sheet1!I29,Sheet1!L29,Sheet1!O29,Sheet1!R29,Sheet1!U29,Sheet1!X29,Sheet1!AA29,Sheet1!AD29,Sheet1!AG29), 0) -> 50
A12: Average Points | B12: Average Knockouts per game
A13: =AVERAGE(Sheet1!D29,Sheet1!G29,Sheet1!J29,Sheet1!M29,Sheet1!P29,Sheet1!S29,Sheet1!V29,Sheet1!Y29,Sheet1!AB29,Sheet1!AE29) -> 0.7 | B13: =AVERAGE(B27:L36) -> 1
A15: Most Re-Buys in a single game | B15: Bubble Finishes
A16: =MAX(B23:L23) -> 0 | B16: 0
A18: Rival Player | B18: Bullied Player
A19: =INDEX(A27:A36, MATCH(MAX(M27:M36), M27:M36, 0)) -> Georgina Wearing | B19: =INDEX(A39:A48, MATCH(MAX(M39:M48), M39:M48, 0)) -> Liam Duxbury
A21: Date | B21: 46048 | C21: 46074 | D21: 46102 | E21: 46138 | F21: 46165 | G21: 46200 | H21: 46229 | I21: 46256 | J21: 46291 | K21: 46321 | L21: Final
A22: Total Money Spent | B22: 20
A23: Rebuys | B23: 0
A24: Add-Ons | B24: 10
A25: Profit/Loss | B25: =Sheet1!C29-B22 -> 30 | C25: =Sheet1!F29-C22 -> 0 | D25: =Sheet1!I29-D22 -> 0 | E25: =Sheet1!L29-E22 -> 0 | F25: =Sheet1!O29-F22 -> 0 | G25: =Sheet1!R29-G22 -> 0 | H25: =Sheet1!U29-H22 -> 0 | I25: =Sheet1!X29-I22 -> 0 | J25: =Sheet1!AA29-J22 -> 0 | K25: =Sheet1!AD29-K22 -> 0 | L25: =Sheet1!AG29-L22 -> 0
A26: Player Knockouts | M26: Total
A27: Edward Wearing | M27: =SUM(B27:L27) -> 0 | N27: =M27-M39 -> 0
A28: Georgina Wearing | B28: 1 | M28: =SUM(B28:L28) -> 1 | N28: =M28-M40 -> 1
A29: Daniel Horne | M29: =SUM(B29:L29) -> 0 | N29: =M29-M41 -> 0
A30: Darren Daly | M30: =SUM(B30:L30) -> 0 | N30: =M30-M42 -> 0
A31: Chris Daly | M31: =SUM(B31:L31) -> 0 | N31: =M31-M43 -> 0
A32: Stephen Flood | M32: =SUM(B32:L32) -> 0 | N32: =M32-M44 -> 0
A33: Phill Landsberger | M33: =SUM(B33:L33) -> 0 | N33: =M33-M45 -> 0
A34: Liam Duxbury | B34: 1 | M34: =SUM(B34:L34) -> 1 | N34: =M34-M46 -> 0
A35: Nathen Benson | B35: 1 | M35: =SUM(B35:L35) -> 1 | N35: =M35-M47 -> 1
A36: Dave Taylor | M36: =SUM(B36:L36) -> 0 | N36: =M36-M48 -> 0
A37: Total | B37: =SUM(B27:B36) -> 3 | C37: =SUM(C27:C36) -> 0 | D37: =SUM(D27:D36) -> 0 | E37: =SUM(E27:E36) -> 0 | F37: =SUM(F27:F36) -> 0 | G37: =SUM(G27:G36) -> 0 | H37: =SUM(H27:H36) -> 0 | I37: =SUM(I27:I36) -> 0 | ... L37: =SUM(L27:L36) -> 0
A38: Knocked Out By | M38: Total
A39: Edward Wearing | M39: =SUM(B39:L39) -> 0
A40: Georgina Wearing | M40: =SUM(B40:L40) -> 0
A41: Daniel Horne | M41: =SUM(B41:L41) -> 0
A42: Darren Daly | M42: =SUM(B42:L42) -> 0
A43: Chris Daly | M43: =SUM(B43:L43) -> 0
A44: Stephen Flood | M44: =SUM(B44:L44) -> 0
A45: Phill Landsberger | M45: =SUM(B45:L45) -> 0
A46: Liam Duxbury | B46: 1 | M46: =SUM(B46:L46) -> 1
...

Sheet Daniel Horne
A1: DANIEL HORNE
A2: E.P.T.2027 Leaderboard Profile
A3: Current Rank | B3: Current League Points
A4: =Sheet1!Y10 -> 6 | B4: =Sheet1!F10 -> 1
A6: Season Profit/Loss | B6: Win Percentage
A7: =Sheet1!P10 -> -20 | B7: =IFERROR(Sheet1!D10/Sheet1!B10, 0) -> 0
A9: Average Finishing Position | B9: Average Winnings
A10: =IFERROR(AVERAGE(Sheet1!B30,Sheet1!E30,Sheet1!H30,Sheet1!K30,Sheet1!N30,Sheet1!Q30,Sheet1!T30,Sheet1!W30,Sheet1!Z30,Sheet1!AC30,Sheet1!AF30), 0) -> 9 | B10: =IFERROR(AVERAGE(Sheet1!C30,Sheet1!F30,Sheet1!I30,Sheet1!L30,Sheet1!O30,Sheet1!R30,Sheet1!U30,Sheet1!X30,Sheet1!AA30,Sheet1!AD30,Sheet1!AG30), 0) -> 0
A12: Average Points | B12: Average Knockouts per game
A13: =AVERAGE(Sheet1!D30,Sheet1!G30,Sheet1!J30,Sheet1!M30,Sheet1!P30,Sheet1!S30,Sheet1!V30,Sheet1!Y30,Sheet1!AB30,Sheet1!AE30) -> 0 | B13: =AVERAGE(B27:L36) -> #DIV/0!
A15: Most Re-Buys in a single game | B15: Bubble Finishes
A16: =MAX(B23:L23) -> 0 | B16: 0
A18: Rival Player | B18: Bullied Player
A19: =INDEX(A27:A36, MATCH(MAX(M27:M36), M27:M36, 0)) -> Edward Wearing | B19: =INDEX(A39:A48, MATCH(MAX(M39:M48), M39:M48, 0)) -> Liam Duxbury
A21: Date | B21: 46048 | C21: 46074 | D21: 46102 | E21: 46138 | F21: 46165 | G21: 46200 | H21: 46229 | I21: 46256 | J21: 46291 | K21: 46321 | L21: Final
A22: Total Money Spent | B22: 20
A23: Rebuys | B23: 0
A24: Add-Ons | B24: 10
A25: Profit/Loss | B25: =Sheet1!C30-B22 -> -20 | C25: =Sheet1!F30-C22 -> 0 | D25: =Sheet1!I30-D22 -> 0 | E25: =Sheet1!L30-E22 -> 0 | F25: =Sheet1!O30-F22 -> 0 | G25: =Sheet1!R30-G22 -> 0 | H25: =Sheet1!U30-H22 -> 0 | I25: =Sheet1!X30-I22 -> 0 | J25: =Sheet1!AA30-J22 -> 0 | K25: =Sheet1!AD30-K22 -> 0 | L25: =Sheet1!AG30-L22 -> 0
A26: Player Knockouts | M26: Total
A27: Edward Wearing | M27: =SUM(B28:L28) -> 0 | N27: =M28-M39 -> 0
A28: Georgina Wearing | M28: =SUM(B28:L28) -> 0 | N28: =M28-M40 -> 0
A29: Luke Daly | M29: =SUM(B29:L29) -> 0 | N29: =M29-M41 -> 0
A30: Darren Daly | M30: =SUM(B30:L30) -> 0 | N30: =M30-M42 -> 0
A31: Chris Daly | M31: =SUM(B31:L31) -> 0 | N31: =M31-M43 -> 0
A32: Stephen Flood | M32: =SUM(B32:L32) -> 0 | N32: =M32-M44 -> 0
A33: Phill Landsberger | M33: =SUM(B33:L33) -> 0 | N33: =M33-M45 -> 0
A34: Liam Duxbury | M34: =SUM(B34:L34) -> 0 | N34: =M34-M46 -> -1
A35: Nathen Benson | M35: =SUM(B35:L35) -> 0 | N35: =M35-M47 -> 0
A36: Dave Taylor | M36: =SUM(B36:L36) -> 0 | N36: =M36-M48 -> 0
A37: Total | B37: =SUM(B28:B36) -> 0 | C37: =SUM(C28:C36) -> 0 | D37: =SUM(D28:D36) -> 0 | E37: =SUM(E28:E36) -> 0 | F37: =SUM(F28:F36) -> 0 | G37: =SUM(G28:G36) -> 0 | H37: =SUM(H28:H36) -> 0 | I37: =SUM(I28:I36) -> 0 | ... L37: =SUM(L28:L36) -> 0
A38: Knocked Out By | M38: Total
A39: Edward Wearing | M39: =SUM(B39:L39) -> 0
A40: Georgina Wearing | M40: =SUM(B40:L40) -> 0
A41: Luke Daly | M41: =SUM(B41:L41) -> 0
A42: Darren Daly | M42: =SUM(B42:L42) -> 0
A43: Chris Daly | M43: =SUM(B43:L43) -> 0
A44: Stephen Flood | M44: =SUM(B44:L44) -> 0
A45: Phill Landsberger | M45: =SUM(B45:L45) -> 0
A46: Liam Duxbury | B46: 1 | M46: =SUM(B46:L46) -> 1
...

Sheet Darren Daly
A1: DARREN DALY
A2: E.P.T.2028 Leaderboard Profile
A3: Current Rank | B3: Current League Points
A4: =Sheet1!Y11 -> 5 | B4: =Sheet1!F11 -> 4
A6: Season Profit/Loss | B6: Win Percentage
A7: =Sheet1!P11 -> -20 | B7: =IFERROR(Sheet1!D11/Sheet1!B11, 0) -> 0
A9: Average Finishing Position | B9: Average Winnings
A10: =IFERROR(AVERAGE(Sheet1!B31,Sheet1!E31,Sheet1!H31,Sheet1!K31,Sheet1!N31,Sheet1!Q31,Sheet1!T31,Sheet1!W31,Sheet1!Z31,Sheet1!AC31,Sheet1!AF31), 0) -> 5 | B10: =IFERROR(AVERAGE(Sheet1!C31,Sheet1!F31,Sheet1!I31,Sheet1!L31,Sheet1!O31,Sheet1!R31,Sheet1!U31,Sheet1!X31,Sheet1!AA31,Sheet1!AD31,Sheet1!AG31), 0) -> 0
A12: Average Points | B12: Average Knockouts per game
A13: =AVERAGE(Sheet1!D31,Sheet1!G31,Sheet1!J31,Sheet1!M31,Sheet1!P31,Sheet1!S31,Sheet1!V31,Sheet1!Y31,Sheet1!AB31,Sheet1!AE31) -> 0.3 | B13: =AVERAGE(B27:L36) -> #DIV/0!
A15: Most Re-Buys in a single game | B15: Bubble Finishes
A16: =MAX(B23:L23) -> 0 | B16: 0
A18: Rival Player | B18: Bullied Player
A19: =INDEX(A27:A36, MATCH(MAX(M27:M36), M27:M36, 0)) -> Edward Wearing | B19: =INDEX(A39:A48, MATCH(MAX(M39:M48), M39:M48, 0)) -> Liam Duxbury
A21: Date | B21: 46048 | C21: 46074 | D21: 46102 | E21: 46138 | F21: 46165 | G21: 46201 | H21: 46229 | I21: 46256 | J21: 46291 | K21: 46321 | L21: Final
A22: Total Money Spent | B22: 20
A23: Rebuys | B23: 0
A24: Add-Ons | B24: 10
A25: Profit/Loss | B25: =Sheet1!C31-B22 -> -20 | C25: =Sheet1!F31-C22 -> 0 | D25: =Sheet1!I31-D22 -> 0 | E25: =Sheet1!L31-E22 -> 0 | F25: =Sheet1!O31-F22 -> 0 | G25: =Sheet1!R31-G22 -> 0 | H25: =Sheet1!U31-H22 -> 0 | I25: =Sheet1!X31-I22 -> 0 | J25: =Sheet1!AA31-J22 -> 0 | K25: =Sheet1!AD31-K22 -> 0 | L25: =Sheet1!AG31-L22 -> 0
A26: Player Knockouts | M26: Total
A27: Edward Wearing | M27: =SUM(B29:L29) -> 0 | N27: =M29-M39 -> 0
A28: Georgina Wearing | M28: =SUM(B29:L29) -> 0 | N28: =M29-M40 -> 0
A29: Luke Daly | M29: =SUM(B29:L29) -> 0 | N29: =M29-M41 -> 0
A30: Daniel Horne | M30: =SUM(B30:L30) -> 0 | N30: =M30-M42 -> 0
A31: Chris Daly | M31: =SUM(B31:L31) -> 0 | N31: =M31-M43 -> 0
A32: Stephen Flood | M32: =SUM(B32:L32) -> 0 | N32: =M32-M44 -> 0
A33: Phill Landsberger | M33: =SUM(B33:L33) -> 0 | N33: =M33-M45 -> 0
A34: Liam Duxbury | M34: =SUM(B34:L34) -> 0 | N34: =M34-M46 -> -1
A35: Nathen Benson | M35: =SUM(B35:L35) -> 0 | N35: =M35-M47 -> 0
A36: Dave Taylor | M36: =SUM(B36:L36) -> 0 | N36: =M36-M48 -> 0
A37: Total | B37: =SUM(B29:B36) -> 0 | C37: =SUM(C29:C36) -> 0 | D37: =SUM(D29:D36) -> 0 | E37: =SUM(E29:E36) -> 0 | F37: =SUM(F29:F36) -> 0 | G37: =SUM(G29:G36) -> 0 | H37: =SUM(H29:H36) -> 0 | I37: =SUM(I29:I36) -> 0 | ... L37: =SUM(L29:L36) -> 0
A38: Knocked Out By | M38: Total
A39: Edward Wearing | M39: =SUM(B39:L39) -> 0
A40: Georgina Wearing | M40: =SUM(B40:L40) -> 0
A41: Luke Daly | M41: =SUM(B41:L41) -> 0
A42: Daniel Horne | M42: =SUM(B42:L42) -> 0
A43: Chris Daly | M43: =SUM(B43:L43) -> 0
A44: Stephen Flood | M44: =SUM(B44:L44) -> 0
A45: Phill Landsberger | M45: =SUM(B45:L45) -> 0
A46: Liam Duxbury | B46: 1 | M46: =SUM(B46:L46) -> 1
...

Sheet Chris Daly
A1: CHRIS DALY
A2: E.P.T.2029 Leaderboard Profile
A3: Current Rank | B3: Current League Points
A4: =Sheet1!Y12 -> 6 | B4: =Sheet1!F12 -> 1
A6: Season Profit/Loss | B6: Win Percentage
A7: =Sheet1!P12 -> -30 | B7: =IFERROR(Sheet1!D12/Sheet1!B12, 0) -> 0
A9: Average Finishing Position | B9: Average Winnings
A10: =IFERROR(AVERAGE(Sheet1!B32,Sheet1!E32,Sheet1!H32,Sheet1!K32,Sheet1!N32,Sheet1!Q32,Sheet1!T32,Sheet1!W32,Sheet1!Z32,Sheet1!AC32,Sheet1!AF32), 0) -> 6 | B10: =IFERROR(AVERAGE(Sheet1!C32,Sheet1!F32,Sheet1!I32,Sheet1!L32,Sheet1!O32,Sheet1!R32,Sheet1!U32,Sheet1!X32,Sheet1!AA32,Sheet1!AD32,Sheet1!AG32), 0) -> 0
A12: Average Points | B12: Average Knockouts per game
A13: =AVERAGE(Sheet1!D32,Sheet1!G32,Sheet1!J32,Sheet1!M32,Sheet1!P32,Sheet1!S32,Sheet1!V32,Sheet1!Y32,Sheet1!AB32,Sheet1!AE32) -> 0 | B13: =AVERAGE(B27:L36) -> 1
A15: Most Re-Buys in a single game | B15: Bubble Finishes
A16: =MAX(B23:L23) -> 10 | B16: 0
A18: Rival Player | B18: Bullied Player
A19: =INDEX(A27:A36, MATCH(MAX(M27:M36), M27:M36, 0)) -> Liam Duxbury | B19: =INDEX(A39:A48, MATCH(MAX(M39:M48), M39:M48, 0)) -> Edward Wearing
A21: Date | B21: 46048 | C21: 46074 | D21: 46102 | E21: 46138 | F21: 46165 | G21: 46202 | H21: 46229 | I21: 46256 | J21: 46291 | K21: 46321 | L21: Final
A22: Total Money Spent | B22: 30
A23: Rebuys | B23: 10
A24: Add-Ons | B24: 10
A25: Profit/Loss | B25: =Sheet1!C32-B22 -> -30 | C25: =Sheet1!F32-C22 -> 0 | D25: =Sheet1!I32-D22 -> 0 | E25: =Sheet1!L32-E22 -> 0 | F25: =Sheet1!O32-F22 -> 0 | G25: =Sheet1!R32-G22 -> 0 | H25: =Sheet1!U32-H22 -> 0 | I25: =Sheet1!X32-I22 -> 0 | J25: =Sheet1!AA32-J22 -> 0 | K25: =Sheet1!AD32-K22 -> 0 | L25: =Sheet1!AG32-L22 -> 0
A26: Player Knockouts | M26: Total
A27: Edward Wearing | M27: =SUM(B29:L29) -> 0 | N27: =M29-M39 -> 0
A28: Georgina Wearing | B28: 1 | M28: =SUM(B29:L29) -> 0 | N28: =M29-M40 -> 0
A29: Luke Daly | M29: =SUM(B29:L29) -> 0 | N29: =M29-M41 -> 0
A30: Daniel Horne | M30: =SUM(B30:L30) -> 0 | N30: =M30-M42 -> 0
A31: Darren Daly | M31: =SUM(B31:L31) -> 0 | N31: =M31-M43 -> 0
A32: Stephen Flood | M32: =SUM(B32:L32) -> 0 | N32: =M32-M44 -> 0
A33: Phill Landsberger | M33: =SUM(B33:L33) -> 0 | N33: =M33-M45 -> 0
A34: Liam Duxbury | B34: 1 | M34: =SUM(B34:L34) -> 1 | N34: =M34-M46 -> 1
A35: Nathen Benson | M35: =SUM(B35:L35) -> 0 | N35: =M35-M47 -> 0
A36: Dave Taylor | M36: =SUM(B36:L36) -> 0 | N36: =M36-M48 -> 0
A37: Total | B37: =SUM(B29:B36) -> 1 | C37: =SUM(C29:C36) -> 0 | D37: =SUM(D29:D36) -> 0 | E37: =SUM(E29:E36) -> 0 | F37: =SUM(F29:F36) -> 0 | G37: =SUM(G29:G36) -> 0 | H37: =SUM(H29:H36) -> 0 | I37: =SUM(I29:I36) -> 0 | ... L37: =SUM(L29:L36) -> 0
A38: Knocked Out By | M38: Total
A39: Edward Wearing | M39: =SUM(B39:L39) -> 0
A40: Georgina Wearing | M40: =SUM(B40:L40) -> 0
A41: Luke Daly | M41: =SUM(B41:L41) -> 0
A42: Daniel Horne | M42: =SUM(B42:L42) -> 0
A43: Darren Daly | M43: =SUM(B43:L43) -> 0
A44: Stephen Flood | M44: =SUM(B44:L44) -> 0
A45: Phill Landsberger | M45: =SUM(B45:L45) -> 0
A46: Liam Duxbury | M46: =SUM(B46:L46) -> 0
...

Sheet Stephen Flood
A1: STEPHEN FLOOD
A2: E.P.T.2030 Leaderboard Profile
A3: Current Rank | B3: Current League Points
A4: =Sheet1!Y13 -> 10 | B4: =Sheet1!F13 -> 0
A6: Season Profit/Loss | B6: Win Percentage
A7: =Sheet1!P13 -> 0 | B7: =IFERROR(Sheet1!D13/Sheet1!B13, 0) -> 0
A9: Average Finishing Position | B9: Average Winnings
A10: =IFERROR(AVERAGE(Sheet1!B33,Sheet1!E33,Sheet1!H33,Sheet1!K33,Sheet1!N33,Sheet1!Q33,Sheet1!T33,Sheet1!W33,Sheet1!Z33,Sheet1!AC33,Sheet1!AF33), 0) -> 0 | B10: =IFERROR(AVERAGE(Sheet1!C33,Sheet1!F33,Sheet1!I33,Sheet1!L33,Sheet1!O33,Sheet1!R33,Sheet1!U33,Sheet1!X33,Sheet1!AA33,Sheet1!AD33,Sheet1!AG33), 0) -> 0
A12: Average Points | B12: Average Knockouts per game
A13: =AVERAGE(Sheet1!D33,Sheet1!G33,Sheet1!J33,Sheet1!M33,Sheet1!P33,Sheet1!S33,Sheet1!V33,Sheet1!Y33,Sheet1!AB33,Sheet1!AE33) -> 0 | B13: =AVERAGE(B27:L36) -> #DIV/0!
A15: Most Re-Buys in a single game | B15: Bubble Finishes
A16: =MAX(B23:L23) -> 0 | B16: 0
A18: Rival Player | B18: Bullied Player
A19: =INDEX(A27:A36, MATCH(MAX(M27:M36), M27:M36, 0)) -> Edward Wearing | B19: =INDEX(A39:A48, MATCH(MAX(M39:M48), M39:M48, 0)) -> Edward Wearing
A21: Date | B21: 46048 | C21: 46074 | D21: 46102 | E21: 46138 | F21: 46165 | G21: 46203 | H21: 46229 | I21: 46256 | J21: 46291 | K21: 46321 | L21: Final
A22: Total Money Spent
A23: Rebuys
A24: Add-Ons
A25: Profit/Loss | B25: =Sheet1!C33-B22 -> 0 | C25: =Sheet1!F33-C22 -> 0 | D25: =Sheet1!I33-D22 -> 0 | E25: =Sheet1!L33-E22 -> 0 | F25: =Sheet1!O33-F22 -> 0 | G25: =Sheet1!R33-G22 -> 0 | H25: =Sheet1!U33-H22 -> 0 | I25: =Sheet1!X33-I22 -> 0 | J25: =Sheet1!AA33-J22 -> 0 | K25: =Sheet1!AD33-K22 -> 0 | L25: =Sheet1!AG33-L22 -> 0
A26: Player Knockouts | M26: Total
A27: Edward Wearing | M27: =SUM(B30:L30) -> 0 | N27: =M30-M39 -> 0
A28: Georgina Wearing | M28: =SUM(B30:L30) -> 0 | N28: =M30-M40 -> 0
A29: Luke Daly | M29: =SUM(B30:L30) -> 0 | N29: =M30-M41 -> 0
A30: Daniel Horne | M30: =SUM(B30:L30) -> 0 | N30: =M30-M42 -> 0
A31: Darren Daly | M31: =SUM(B31:L31) -> 0 | N31: =M31-M43 -> 0
A32: Chris Daly | M32: =SUM(B32:L32) -> 0 | N32: =M32-M44 -> 0
A33: Phill Landsberger | M33: =SUM(B33:L33) -> 0 | N33: =M33-M45 -> 0
A34: Liam Duxbury | M34: =SUM(B34:L34) -> 0 | N34: =M34-M46 -> 0
A35: Nathen Benson | M35: =SUM(B35:L35) -> 0 | N35: =M35-M47 -> 0
A36: Dave Taylor | M36: =SUM(B36:L36) -> 0 | N36: =M36-M48 -> 0
A37: Total | B37: =SUM(B30:B36) -> 0 | C37: =SUM(C30:C36) -> 0 | D37: =SUM(D30:D36) -> 0 | E37: =SUM(E30:E36) -> 0 | F37: =SUM(F30:F36) -> 0 | G37: =SUM(G30:G36) -> 0 | H37: =SUM(H30:H36) -> 0 | I37: =SUM(I30:I36) -> 0 | ... L37: =SUM(L30:L36) -> 0
A38: Knocked Out By | M38: Total
A39: Edward Wearing | M39: =SUM(B39:L39) -> 0
A40: Georgina Wearing | M40: =SUM(B40:L40) -> 0
A41: Luke Daly | M41: =SUM(B41:L41) -> 0
A42: Daniel Horne | M42: =SUM(B42:L42) -> 0
A43: Darren Daly | M43: =SUM(B43:L43) -> 0
A44: Chris Daly | M44: =SUM(B44:L44) -> 0
A45: Phill Landsberger | M45: =SUM(B45:L45) -> 0
A46: Liam Duxbury | M46: =SUM(B46:L46) -> 0
...

Sheet Phil Landsberger
A1: PHIL LANDSBERGER
A2: E.P.T.2031 Leaderboard Profile
A3: Current Rank | B3: Current League Points
A4: =Sheet1!Y14 -> 10 | B4: =Sheet1!F14 -> 0
A6: Season Profit/Loss | B6: Win Percentage
A7: =Sheet1!P14 -> 0 | B7: =IFERROR(Sheet1!D14/Sheet1!B14, 0) -> 0
A9: Average Finishing Position | B9: Average Winnings
A10: =IFERROR(AVERAGE(Sheet1!B34,Sheet1!E34,Sheet1!H34,Sheet1!K34,Sheet1!N34,Sheet1!Q34,Sheet1!T34,Sheet1!W34,Sheet1!Z34,Sheet1!AC34,Sheet1!AF34), 0) -> 0 | B10: =IFERROR(AVERAGE(Sheet1!C34,Sheet1!F34,Sheet1!I34,Sheet1!L34,Sheet1!O34,Sheet1!R34,Sheet1!U34,Sheet1!X34,Sheet1!AA34,Sheet1!AD34,Sheet1!AG34), 0) -> 0
A12: Average Points | B12: Average Knockouts per game
A13: =AVERAGE(Sheet1!D34,Sheet1!G34,Sheet1!J34,Sheet1!M34,Sheet1!P34,Sheet1!S34,Sheet1!V34,Sheet1!Y34,Sheet1!AB34,Sheet1!AE34) -> 0 | B13: =AVERAGE(B27:L36) -> #DIV/0!
A15: Most Re-Buys in a single game | B15: Bubble Finishes
A16: =MAX(B23:L23) -> 0 | B16: 0
A18: Rival Player | B18: Bullied Player
A19: =INDEX(A27:A36, MATCH(MAX(M27:M36), M27:M36, 0)) -> Edward Wearing | B19: =INDEX(A39:A48, MATCH(MAX(M39:M48), M39:M48, 0)) -> Edward Wearing
A21: Date | B21: 46048 | C21: 46074 | D21: 46102 | E21: 46138 | F21: 46165 | G21: 31/06/2026 | H21: 46229 | I21: 46256 | J21: 46291 | K21: 46321 | L21: Final
A22: Total Money Spent
A23: Rebuys
A24: Add-Ons
A25: Profit/Loss | B25: =Sheet1!C34-B22 -> 0 | C25: =Sheet1!F34-C22 -> 0 | D25: =Sheet1!I34-D22 -> 0 | E25: =Sheet1!L34-E22 -> 0 | F25: =Sheet1!O34-F22 -> 0 | G25: =Sheet1!R34-G22 -> 0 | H25: =Sheet1!U34-H22 -> 0 | I25: =Sheet1!X34-I22 -> 0 | J25: =Sheet1!AA34-J22 -> 0 | K25: =Sheet1!AD34-K22 -> 0 | L25: =Sheet1!AG34-L22 -> 0
A26: Player Knockouts | M26: Total
A27: Edward Wearing | M27: =SUM(B31:L31) -> 0 | N27: =M31-M39 -> 0
A28: Georgina Wearing | M28: =SUM(B31:L31) -> 0 | N28: =M31-M40 -> 0
A29: Luke Daly | M29: =SUM(B31:L31) -> 0 | N29: =M31-M41 -> 0
A30: Daniel Horne | M30: =SUM(B31:L31) -> 0 | N30: =M31-M42 -> 0
A31: Darren Daly | M31: =SUM(B31:L31) -> 0 | N31: =M31-M43 -> 0
A32: Chris Daly | M32: =SUM(B32:L32) -> 0 | N32: =M32-M44 -> 0
A33: Stephen Flood | M33: =SUM(B33:L33) -> 0 | N33: =M33-M45 -> 0
A34: Liam Duxbury | M34: =SUM(B34:L34) -> 0 | N34: =M34-M46 -> 0
A35: Nathen Benson | M35: =SUM(B35:L35) -> 0 | N35: =M35-M47 -> 0
A36: Dave Taylor | M36: =SUM(B36:L36) -> 0 | N36: =M36-M48 -> 0
A37: Total | B37: =SUM(B31:B36) -> 0 | C37: =SUM(C31:C36) -> 0 | D37: =SUM(D31:D36) -> 0 | E37: =SUM(E31:E36) -> 0 | F37: =SUM(F31:F36) -> 0 | G37: =SUM(G31:G36) -> 0 | H37: =SUM(H31:H36) -> 0 | I37: =SUM(I31:I36) -> 0 | ... L37: =SUM(L31:L36) -> 0
A38: Knocked Out By | M38: Total
A39: Edward Wearing | M39: =SUM(B39:L39) -> 0
A40: Georgina Wearing | M40: =SUM(B40:L40) -> 0
A41: Luke Daly | M41: =SUM(B41:L41) -> 0
A42: Daniel Horne | M42: =SUM(B42:L42) -> 0
A43: Darren Daly | M43: =SUM(B43:L43) -> 0
A44: Chris Daly | M44: =SUM(B44:L44) -> 0
A45: Stephen Flood | M45: =SUM(B45:L45) -> 0
A46: Liam Duxbury | M46: =SUM(B46:L46) -> 0
...

Sheet Liam Duxbury
A1: LIAM DUXBURY
A2: E.P.T.2032 Leaderboard Profile
A3: Current Rank | B3: Current League Points
A4: =Sheet1!Y15 -> 1 | B4: =Sheet1!F15 -> 17
A6: Season Profit/Loss | B6: Win Percentage
A7: =Sheet1!P15 -> 80 | B7: =IFERROR(Sheet1!D15/Sheet1!B15, 0) -> 1
A9: Average Finishing Position | B9: Average Winnings
A10: =IFERROR(AVERAGE(Sheet1!B35,Sheet1!E35,Sheet1!H35,Sheet1!K35,Sheet1!N35,Sheet1!Q35,Sheet1!T35,Sheet1!W35,Sheet1!Z35,Sheet1!AC35,Sheet1!AF35), 0) -> 1 | B10: =IFERROR(AVERAGE(Sheet1!C35,Sheet1!F35,Sheet1!I35,Sheet1!L35,Sheet1!O35,Sheet1!R35,Sheet1!U35,Sheet1!X35,Sheet1!AA35,Sheet1!AD35,Sheet1!AG35), 0) -> 110
A12: Average Points | B12: Average Knockouts per game
A13: =AVERAGE(Sheet1!D35,Sheet1!G35,Sheet1!J35,Sheet1!M35,Sheet1!P35,Sheet1!S35,Sheet1!V35,Sheet1!Y35,Sheet1!AB35,Sheet1!AE35) -> 1.1 | B13: =AVERAGE(B27:L36) -> 1
A15: Most Re-Buys in a single game | B15: Bubble Finishes
A16: =MAX(B23:L23) -> 10 | B16: 0
A18: Rival Player | B18: Bullied Player
A19: =INDEX(A27:A36, MATCH(MAX(M27:M36), M27:M36, 0)) -> Edward Wearing | B19: =INDEX(A39:A48, MATCH(MAX(M39:M48), M39:M48, 0)) -> Luke Daly
A21: Date | B21: 46048 | C21: 46074 | D21: 46102 | E21: 46138 | F21: 46165 | G21: 32/06/2026 | H21: 46229 | I21: 46256 | J21: 46291 | K21: 46321 | L21: Final
A22: Total Money Spent | B22: 20
A23: Rebuys | B23: 10
A24: Add-Ons | B24: 10
A25: Profit/Loss | B25: =Sheet1!C35-B22 -> 90 | C25: =Sheet1!F35-C22 -> 0 | D25: =Sheet1!I35-D22 -> 0 | E25: =Sheet1!L35-E22 -> 0 | F25: =Sheet1!O35-F22 -> 0 | G25: =Sheet1!R35-G22 -> 0 | H25: =Sheet1!U35-H22 -> 0 | I25: =Sheet1!X35-I22 -> 0 | J25: =Sheet1!AA35-J22 -> 0 | K25: =Sheet1!AD35-K22 -> 0 | L25: =Sheet1!AG35-L22 -> 0
A26: Player Knockouts | M26: Total
A27: Edward Wearing | B27: 1 | M27: =SUM(B32:L32) -> 1 | N27: =M32-M39 -> 1
A28: Georgina Wearing | M28: =SUM(B32:L32) -> 1 | N28: =M32-M40 -> 1
A29: Luke Daly | B29: 1 | M29: =SUM(B32:L32) -> 1 | N29: =M32-M41 -> 0
A30: Daniel Horne | B30: 1 | M30: =SUM(B32:L32) -> 1 | N30: =M32-M42 -> 1
A31: Darren Daly | B31: 1 | M31: =SUM(B32:L32) -> 1 | N31: =M32-M43 -> 1
A32: Chris Daly | B32: 1 | M32: =SUM(B32:L32) -> 1 | N32: =M32-M44 -> 1
A33: Stephen Flood | M33: =SUM(B33:L33) -> 0 | N33: =M33-M45 -> 0
A34: Phil Lansdberger | M34: =SUM(B34:L34) -> 0 | N34: =M34-M46 -> 0
A35: Nathen Benson | M35: =SUM(B35:L35) -> 0 | N35: =M35-M47 -> 0
A36: Dave Taylor | M36: =SUM(B36:L36) -> 0 | N36: =M36-M48 -> 0
A37: Total | B37: =SUM(B32:B36) -> 1 | C37: =SUM(C32:C36) -> 0 | D37: =SUM(D32:D36) -> 0 | E37: =SUM(E32:E36) -> 0 | F37: =SUM(F32:F36) -> 0 | G37: =SUM(G32:G36) -> 0 | H37: =SUM(H32:H36) -> 0 | I37: =SUM(I32:I36) -> 0 | ... L37: =SUM(L32:L36) -> 0
A38: Knocked Out By | M38: Total
A39: Edward Wearing | M39: =SUM(B39:L39) -> 0
A40: Georgina Wearing | M40: =SUM(B40:L40) -> 0
A41: Luke Daly | B41: 1 | M41: =SUM(B41:L41) -> 1
A42: Daniel Horne | M42: =SUM(B42:L42) -> 0
A43: Darren Daly | M43: =SUM(B43:L43) -> 0
A44: Chris Daly | M44: =SUM(B44:L44) -> 0
A45: Stephen Flood | M45: =SUM(B45:L45) -> 0
A46: Phil Lansdberger | M46: =SUM(B46:L46) -> 0
...

Sheet Nathen Benson
A1: NATHEN BENSON
A2: E.P.T.2033 Leaderboard Profile
A3: Current Rank | B3: Current League Points
A4: =Sheet1!Y16 -> 6 | B4: =Sheet1!F16 -> 1
A6: Season Profit/Loss | B6: Win Percentage
A7: =Sheet1!P16 -> -20 | B7: =IFERROR(Sheet1!D16/Sheet1!B16, 0) -> 0
A9: Average Finishing Position | B9: Average Winnings
A10: =IFERROR(AVERAGE(Sheet1!B36,Sheet1!E36,Sheet1!H36,Sheet1!K36,Sheet1!N36,Sheet1!Q36,Sheet1!T36,Sheet1!W36,Sheet1!Z36,Sheet1!AC36,Sheet1!AF36), 0) -> 8 | B10: =IFERROR(AVERAGE(Sheet1!C36,Sheet1!F36,Sheet1!I36,Sheet1!L36,Sheet1!O36,Sheet1!R36,Sheet1!U36,Sheet1!X36,Sheet1!AA36,Sheet1!AD36,Sheet1!AG36), 0) -> 0
A12: Average Points | B12: Average Knockouts per game
A13: =AVERAGE(Sheet1!D36,Sheet1!G36,Sheet1!J36,Sheet1!M36,Sheet1!P36,Sheet1!S36,Sheet1!V36,Sheet1!Y36,Sheet1!AB36,Sheet1!AE36) -> 0 | B13: =AVERAGE(B27:L36) -> #DIV/0!
A15: Most Re-Buys in a single game | B15: Bubble Finishes
A16: =MAX(B23:L23) -> 0 | B16: 0
A18: Rival Player | B18: Bullied Player
A19: =INDEX(A27:A36, MATCH(MAX(M27:M36), M27:M36, 0)) -> Edward Wearing | B19: =INDEX(A39:A48, MATCH(MAX(M39:M48), M39:M48, 0)) -> Luke Daly
A21: Date | B21: 46048 | C21: 46074 | D21: 46102 | E21: 46138 | F21: 46165 | G21: 33/06/2026 | H21: 46229 | I21: 46256 | J21: 46291 | K21: 46321 | L21: Final
A22: Total Money Spent | B22: 20
A23: Rebuys | B23: 0
A24: Add-Ons | B24: 10
A25: Profit/Loss | B25: =Sheet1!C36-B22 -> -20 | C25: =Sheet1!F36-C22 -> 0 | D25: =Sheet1!I36-D22 -> 0 | E25: =Sheet1!L36-E22 -> 0 | F25: =Sheet1!O36-F22 -> 0 | G25: =Sheet1!R36-G22 -> 0 | H25: =Sheet1!U36-H22 -> 0 | I25: =Sheet1!X36-I22 -> 0 | J25: =Sheet1!AA36-J22 -> 0 | K25: =Sheet1!AD36-K22 -> 0 | L25: =Sheet1!AG36-L22 -> 0
A26: Player Knockouts | M26: Total
A27: Edward Wearing | M27: =SUM(B33:L33) -> 0 | N27: =M33-M39 -> 0
A28: Georgina Wearing | M28: =SUM(B33:L33) -> 0 | N28: =M33-M40 -> 0
A29: Luke Daly | M29: =SUM(B33:L33) -> 0 | N29: =M33-M41 -> -1
A30: Daniel Horne | M30: =SUM(B33:L33) -> 0 | N30: =M33-M42 -> 0
A31: Darren Daly | M31: =SUM(B33:L33) -> 0 | N31: =M33-M43 -> 0
A32: Chris Daly | M32: =SUM(B33:L33) -> 0 | N32: =M33-M44 -> 0
A33: Stephen Flood | M33: =SUM(B33:L33) -> 0 | N33: =M33-M45 -> 0
A34: Phil Lansdberger | M34: =SUM(B34:L34) -> 0 | N34: =M34-M46 -> 0
A35: Liam Duxbury | M35: =SUM(B35:L35) -> 0 | N35: =M35-M47 -> 0
A36: Dave Taylor | M36: =SUM(B36:L36) -> 0 | N36: =M36-M48 -> 0
A37: Total | B37: =SUM(B33:B36) -> 0 | C37: =SUM(C33:C36) -> 0 | D37: =SUM(D33:D36) -> 0 | E37: =SUM(E33:E36) -> 0 | F37: =SUM(F33:F36) -> 0 | G37: =SUM(G33:G36) -> 0 | H37: =SUM(H33:H36) -> 0 | I37: =SUM(I33:I36) -> 0 | ... L37: =SUM(L33:L36) -> 0
A38: Knocked Out By | M38: Total
A39: Edward Wearing | M39: =SUM(B39:L39) -> 0
A40: Georgina Wearing | M40: =SUM(B40:L40) -> 0
A41: Luke Daly | B41: 1 | M41: =SUM(B41:L41) -> 1
A42: Daniel Horne | M42: =SUM(B42:L42) -> 0
A43: Darren Daly | M43: =SUM(B43:L43) -> 0
A44: Chris Daly | M44: =SUM(B44:L44) -> 0
A45: Stephen Flood | M45: =SUM(B45:L45) -> 0
A46: Phil Lansdberger | M46: =SUM(B46:L46) -> 0
...

Sheet Dave Taylor
A1: DAVE TAYLOR
A2: E.P.T.2034 Leaderboard Profile
A3: Current Rank | B3: Current League Points
A4: =Sheet1!Y17 -> 6 | B4: =Sheet1!F17 -> 1
A6: Season Profit/Loss | B6: Win Percentage
A7: =Sheet1!P17 -> -20 | B7: =IFERROR(Sheet1!D17/Sheet1!B17, 0) -> 0
A9: Average Finishing Position | B9: Average Winnings
A10: =IFERROR(AVERAGE(Sheet1!B37,Sheet1!E37,Sheet1!H37,Sheet1!K37,Sheet1!N37,Sheet1!Q37,Sheet1!T37,Sheet1!W37,Sheet1!Z37,Sheet1!AC37,Sheet1!AF37), 0) -> 7 | B10: =IFERROR(AVERAGE(Sheet1!C37,Sheet1!F37,Sheet1!I37,Sheet1!L37,Sheet1!O37,Sheet1!R37,Sheet1!U37,Sheet1!X37,Sheet1!AA37,Sheet1!AD37,Sheet1!AG37), 0) -> 0
A12: Average Points | B12: Average Knockouts per game
A13: =AVERAGE(Sheet1!D37,Sheet1!G37,Sheet1!J37,Sheet1!M37,Sheet1!P37,Sheet1!S37,Sheet1!V37,Sheet1!Y37,Sheet1!AB37,Sheet1!AE37) -> 0 | B13: =AVERAGE(B27:L36) -> #DIV/0!
A15: Most Re-Buys in a single game | B15: Bubble Finishes
A16: =MAX(B23:L23) -> 0 | B16: 0
A18: Rival Player | B18: Bullied Player
A19: =INDEX(A27:A36, MATCH(MAX(M27:M36), M27:M36, 0)) -> Edward Wearing | B19: =INDEX(A39:A48, MATCH(MAX(M39:M48), M39:M48, 0)) -> Edward Wearing
A21: Date | B21: 46048 | C21: 46074 | D21: 46102 | E21: 46138 | F21: 46165 | G21: 34/06/2026 | H21: 46229 | I21: 46256 | J21: 46291 | K21: 46321 | L21: Final
A22: Total Money Spent | B22: 20
A23: Rebuys | B23: 0
A24: Add-Ons | B24: 10
A25: Profit/Loss | B25: =Sheet1!C37-B22 -> -20 | C25: =Sheet1!F37-C22 -> 0 | D25: =Sheet1!I37-D22 -> 0 | E25: =Sheet1!L37-E22 -> 0 | F25: =Sheet1!O37-F22 -> 0 | G25: =Sheet1!R37-G22 -> 0 | H25: =Sheet1!U37-H22 -> 0 | I25: =Sheet1!X37-I22 -> 0 | J25: =Sheet1!AA37-J22 -> 0 | K25: =Sheet1!AD37-K22 -> 0 | L25: =Sheet1!AG37-L22 -> 0
A26: Player Knockouts | M26: Total
A27: Edward Wearing | M27: =SUM(B34:L34) -> 0 | N27: =M34-M39 -> -1
A28: Georgina Wearing | M28: =SUM(B34:L34) -> 0 | N28: =M34-M40 -> 0
A29: Luke Daly | M29: =SUM(B34:L34) -> 0 | N29: =M34-M41 -> 0
A30: Daniel Horne | M30: =SUM(B34:L34) -> 0 | N30: =M34-M42 -> 0
A31: Darren Daly | M31: =SUM(B34:L34) -> 0 | N31: =M34-M43 -> 0
A32: Chris Daly | M32: =SUM(B34:L34) -> 0 | N32: =M34-M44 -> 0
A33: Stephen Flood | M33: =SUM(B34:L34) -> 0 | N33: =M34-M45 -> 0
A34: Phil Lansdberger | M34: =SUM(B34:L34) -> 0 | N34: =M34-M46 -> 0
A35: Liam Duxbury | M35: =SUM(B35:L35) -> 0 | N35: =M35-M47 -> 0
A36: Nathen Benson | M36: =SUM(B36:L36) -> 0 | N36: =M36-M48 -> 0
A37: Total | B37: =SUM(B27:B36) -> 0 | C37: =SUM(C27:C36) -> 0 | D37: =SUM(D27:D36) -> 0 | E37: =SUM(E27:E36) -> 0 | F37: =SUM(F27:F36) -> 0 | G37: =SUM(G27:G36) -> 0 | H37: =SUM(H27:H36) -> 0 | I37: =SUM(I27:I36) -> 0 | ... L37: =SUM(L27:L36) -> 0
A38: Knocked Out By | M38: Total
A39: Edward Wearing | B39: 1 | M39: =SUM(B39:L39) -> 1
A40: Georgina Wearing | M40: =SUM(B40:L40) -> 0
A41: Luke Daly | M41: =SUM(B41:L41) -> 0
A42: Daniel Horne | M42: =SUM(B42:L42) -> 0
A43: Darren Daly | M43: =SUM(B43:L43) -> 0
A44: Chris Daly | M44: =SUM(B44:L44) -> 0
A45: Stephen Flood | M45: =SUM(B45:L45) -> 0
A46: Phil Lansdberger | M46: =SUM(B46:L46) -> 0
...
